<?xml version="1.0"?>
<robot xmlns:xacro="http://www.ros.org/wiki/xacro">


    <xacro:property name="body_mass" value="25.0" />
    <xacro:property name="body_x" value="0.75" />  <!-- 길이 (앞뒤) -->
    <xacro:property name="body_y" value="0.28" />   <!-- 폭 (좌우) -->
    <xacro:property name="body_z" value="0.10" />  <!-- 높이 (위아래) -->

    <xacro:property name="wheel_radius" value="0.08" />
    <xacro:property name="wheel_thickness" value="0.06" />
    <xacro:property name="wheel_mass" value="2.0" />
    <xacro:property name="steering_mass" value="0.01" />


    <!-- BASE -->
    <link name="base_footprint">
            <origin xyz="0 0 0" rpy="0 0 0" />
    </link>

    <link name="base_link">
    </link>
    <joint name="base_joint" type="fixed">
        <parent link="base_footprint" />
        <child link="base_link" />
        <origin xyz="0.0 0.0 0.08" rpy="0 0 0" />
    </joint>

    <link name="chassis_link">
        <inertial>
            <origin xyz="0 0 0" rpy="0 0 0" />
            <mass value="2.5" />
            <inertia ixx="${body_mass/12 * (body_y*body_y + body_z*body_z)}"
                ixy="0" ixz="0"
                iyy="${body_mass/12 * (body_x*body_x + body_z*body_z)}" iyz="0"
                izz="${body_mass/12 * (body_x*body_x + body_y*body_y)}" />
        </inertial>
        <visual>
            <origin xyz="0 0 0" rpy="0 0 0" />
            <geometry>
                <box size="${body_x} ${body_y} ${body_z}" />
            </geometry>
        </visual>
        <collision>
            <origin xyz="0 0 0" rpy="0 0 0" />
            <geometry>
                <box size="${body_x} ${body_y} ${body_z}" />
            </geometry>
        </collision>
    </link>
    <joint name="chassis_joint" type="fixed">
        <parent link="base_link" />
        <child link="chassis_link" />
        <origin xyz="0.0 0.0 0.05" rpy="0 0 0" />
    </joint>


    <!-- FRONT LEFT WHEEL -->
    <link name="fr_left_steer_link">
        <inertial>
            <origin xyz="-0.0002776492198312 0.0163539773588368 4.97346169803237E-09" rpy="0 0 0" />
            <mass value="${steering_mass}" />
            <inertia
                ixx="${steering_mass/12*(3*wheel_radius*wheel_radius + wheel_thickness*wheel_thickness)}"
                ixy="0" ixz="0"
                iyy="${steering_mass/12*(3*wheel_radius*wheel_radius + wheel_thickness*wheel_thickness)}"
                iyz="0" izz="${steering_mass/2 * wheel_radius*wheel_radius}" />
        </inertial>
    </link>
    <joint name="fr_left_steer_joint" type="revolute">
        <origin xyz="0.275 0.25 -0.05" rpy="0 0 0" />
        <parent link="chassis_link" />
        <child link="fr_left_steer_link" />
        <axis xyz="0 0 1" />
        <limit upper="0.6109" lower="-0.6109" effort="-1.0" velocity="-1.0" />
    </joint>
    <link name="fr_left_wheel_link">
        <inertial>
            <origin xyz="-3.5837499634539E-10 4.97346158701006E-09 -0.016356334080185" rpy="0 0 0" />
            <mass value="${wheel_mass}" />
            <inertia
                ixx="${wheel_mass/12*(3*wheel_radius*wheel_radius + wheel_thickness*wheel_thickness)}"
                ixy="0" ixz="0"
                iyy="${wheel_mass/12*(3*wheel_radius*wheel_radius + wheel_thickness*wheel_thickness)}"
                iyz="0" izz="${wheel_mass/2 * wheel_radius*wheel_radius}" />
        </inertial>
        <visual>
            <origin xyz="0 0 0" rpy="0 0 0" />
            <geometry>
                <cylinder radius="${wheel_radius}" length="${wheel_thickness}" />
            </geometry>
            <material name="">
                <color rgba="0.223529411764706 0.223529411764706 0.223529411764706 1" />
            </material>
        </visual>
        <collision>
            <origin xyz="0 0 0" rpy="0 0 0" />
            <geometry>
                <cylinder radius="${wheel_radius}" length="${wheel_thickness}" />
            </geometry>
        </collision>
    </link>
    <joint name="fr_left_wheel_joint" type="continuous">
        <origin xyz="0 0 0" rpy="1.5708 0 0" />
        <parent link="fr_left_steer_link" />
        <child link="fr_left_wheel_link" />
        <axis xyz="0 0 -1" />
        <dynamics friction="0.8" damping="0.5" />
        <limit lower="-3.14159" upper="3.14159" effort="200" velocity="-1" />


    </joint>


    <!-- FRONT RIGHT WHEEL -->
    <link name="fr_right_steer_link">
        <inertial>
            <origin xyz="0.000274981985673328 -0.0163540222836661 -3.24802407192237E-11" rpy="0 0 0" />
            <mass value="${steering_mass}" />
            <inertia
                ixx="${steering_mass/12*(3*wheel_radius*wheel_radius + wheel_thickness*wheel_thickness)}"
                ixy="0" ixz="0"
                iyy="${steering_mass/12*(3*wheel_radius*wheel_radius + wheel_thickness*wheel_thickness)}"
                iyz="0" izz="${steering_mass/2 * wheel_radius*wheel_radius}" />
        </inertial>
    </link>
    <joint name="fr_right_steer_joint" type="revolute">
        <origin xyz="0.275 -0.25 -0.05" rpy="0 0 0" />
        <parent link="chassis_link" />
        <child link="fr_right_steer_link" />
        <axis xyz="0 0 1" />
        <limit upper="0.6109" lower="-0.6109" effort="-1.0" velocity="-1.0" />
    </joint>
    <link name="fr_right_wheel_link">
        <inertial>
            <origin xyz="0.00027498198567355 3.24801296969213E-11 -0.0163540222836661" rpy="0 0 0" />
            <mass value="${wheel_mass}" />
            <inertia
                ixx="${wheel_mass/12*(3*wheel_radius*wheel_radius + wheel_thickness*wheel_thickness)}"
                ixy="0" ixz="0"
                iyy="${wheel_mass/12*(3*wheel_radius*wheel_radius + wheel_thickness*wheel_thickness)}"
                iyz="0" izz="${wheel_mass/2 * wheel_radius*wheel_radius}" />
        </inertial>
        <visual>
            <origin xyz="0 0 0" rpy="0 0 0" />
            <geometry>
                <cylinder radius="${wheel_radius}" length="${wheel_thickness}" />
            </geometry>
            <material name="">
                <color rgba="0.223529411764706 0.223529411764706 0.223529411764706 1" />
            </material>
        </visual>
        <collision>
            <origin xyz="0 0 0" rpy="0 0 0" />
            <geometry>
                <cylinder radius="${wheel_radius}" length="${wheel_thickness}" />
            </geometry>
        </collision>
    </link>
    <joint name="fr_right_wheel_joint" type="continuous">
        <origin xyz="0 0 0" rpy="-1.5708 0 0" />
        <parent link="fr_right_steer_link" />
        <child link="fr_right_wheel_link" />
        <axis xyz="0 0 1" />
        <dynamics friction="0.8" damping="0.5" />
        <limit lower="-3.14159" upper="3.14159" effort="200" velocity="-1" />


    </joint>


    <!-- REAR LEFT WHEEL -->
    <link name="re_left_wheel_link">
        <inertial>
            <origin xyz="1.245E-09 1.7252E-06 -0.010284" rpy="0 0 0" />
            <mass value="${wheel_mass}" />
            <inertia
                ixx="${wheel_mass/12*(3*wheel_radius*wheel_radius + wheel_thickness*wheel_thickness)}"
                ixy="0" ixz="0"
                iyy="${wheel_mass/12*(3*wheel_radius*wheel_radius + wheel_thickness*wheel_thickness)}"
                iyz="0" izz="${wheel_mass/2 * wheel_radius*wheel_radius}" />
        </inertial>
        <visual>
            <origin xyz="0 0 0" rpy="0 0 0" />
            <geometry>
                <cylinder radius="${wheel_radius}" length="${wheel_thickness}" />
            </geometry>
            <material name="">
                <color rgba="0.37647 0.37647 0.37647 1" />
            </material>
        </visual>
        <collision>
            <origin xyz="0 0 0" rpy="0 0 0" />
            <geometry>
                <cylinder radius="${wheel_radius}" length="${wheel_thickness}" />
            </geometry>
        </collision>
    </link>
    <joint name="re_left_wheel_joint" type="continuous">
        <origin xyz="-0.275 0.25 -0.05" rpy="1.5708 0 0" />
        <parent link="chassis_link" />
        <child link="re_left_wheel_link" />
        <axis xyz="0 0 -1" />
        <dynamics friction="0.8" damping="0.5" />
        <limit lower="-3.14159" upper="3.14159" effort="70" velocity="-1" />


    </joint>


    <!-- REAR RIGHT WHEEL -->
    <link name="re_right_wheel_link">
        <inertial>
            <origin xyz="0 0 0" rpy="0 0 0" />
            <mass value="${wheel_mass}" />
            <inertia
                ixx="${wheel_mass/12*(3*wheel_radius*wheel_radius + wheel_thickness*wheel_thickness)}"
                ixy="0" ixz="0"
                iyy="${wheel_mass/12*(3*wheel_radius*wheel_radius + wheel_thickness*wheel_thickness)}"
                iyz="0" izz="${wheel_mass/2 * wheel_radius*wheel_radius}" />
        </inertial>
        <visual>
            <origin xyz="0 0 0" rpy="0 0 0" />
            <geometry>
                <cylinder radius="${wheel_radius}" length="${wheel_thickness}" />
            </geometry>
            <material name="">
                <color rgba="0.37647 0.37647 0.37647 1" />
            </material>
        </visual>
        <collision>
            <origin xyz="0 0 0" rpy="0 0 0" />
            <geometry>
                <cylinder radius="${wheel_radius}" length="${wheel_thickness}" />
            </geometry>
        </collision>
    </link>
    <joint name="re_right_wheel_joint" type="continuous">
        <origin xyz="-0.275 -0.25 -0.05" rpy="-1.5708 0 0" />
        <parent link="chassis_link" />
        <child link="re_right_wheel_link" />
        <axis xyz="0 0 1" />

        <dynamics friction="0.8" damping="0.5" />
        <limit lower="-3.14159" upper="3.14159" effort="70" velocity="-1" />
    </joint>



<!-- LASER -->
    <link name="laser_link">
    <visual>
        <geometry>
        <cylinder length="0.03" radius="0.075"/>
        </geometry>
        <origin rpy="0 0 0" xyz="0 0 -0.01"/>
        <material name="rgba(255,255,255,1)">
        <color rgba="1 1 1 1"/>
        </material>
    </visual>
    </link>

    <joint name="laser_joint" type="fixed">
        <parent link="chassis_link"/>
        <child link="laser_link"/>
        <origin rpy="0 0 0" xyz="0.25 0 0.075"/>
    </joint>

<!-- IMU -->
    <link name="imu_link">
        <visual>
            <geometry>
        <box size="0.02 0.02 0.02"/>
            </geometry>
            <origin rpy="0 0 0" xyz="0 0 -0.01"/>
            <material name="rgba(255,255,255,1)">
            <color rgba="1 1 1 1"/>
            </material>
        </visual>
    </link>

    <joint name="imu_joint" type="fixed">
        <parent link="chassis_link"/>
        <child link="imu_link"/>
        <origin rpy="0 0 0" xyz="0 0 0.065"/>
    </joint>

<!-- CAMERA -->
    <link name="camera_link">
        <visual>
            <geometry>
                <box size="0.002 0.025 0.025"/>
            </geometry>
            <origin rpy="0 0 0" xyz="0 0 0"/>
            <material name="">
                <color rgba="0.2 0.2 0.2 1"/>
            </material>
        </visual>
        <collision>
            <origin rpy="0 0 0" xyz="0 0 0"/>
            <geometry>
                <box size="0.002 0.025 0.025"/>
            </geometry>
        </collision>
        <inertial>
            <origin xyz="0 0 0" rpy="0 0 0"/>
            <mass value="0.01"/>
            <inertia ixx="0.001" ixy="0.0" ixz="0.0" iyy="0.001" iyz="0.0" izz="0.001"/>
        </inertial>
    </link>

    <joint name="camera_joint" type="fixed">
        <parent link="chassis_link"/>
        <child link="camera_link"/>
        <origin rpy="0 0.698132 0" xyz="0.32 0 0.16"/>
    </joint>



</robot>
